Workbook

Sheet Title Page
A6: Module: International Boardroom
A7: Name students: Angeline Chatelain (682447), Jessica Redondo Müller (683501), Karla Ostojic (689192), Merel Zwart (655564), Omar Abdulghani (628674)
A8: Class: ICB 2A International Creative Business Haarlem
A9: Project: Financial Plan | E9: Company: | F9: BEEX
A10: Company type: Limited liability company | E10: Number of employees: 2
A11: Businessmodel: | C11: Subscriptions/Packages/Hours
A12: Monthly hours on the basis of subscriptions or tailored per project
A13: Country: Belgium
A14: Currency: Euros
A15: Submission date: 18.12.22

Sheet inv+fin. budget
A1: Investment- and financing budget | H1: Notes
B2: Investment- and financing budget per January 1st, year 2023
A3: Debet | F3: Credit | H3: List Inventory | I3: Incl. VAT | J3: Excl. VAT | K3: Number | L3: Total incl. VAT | M3: Total excl. VAT | N3: Total VAT | O3: Reference url | P3: Additional notes
H4: Desks | I4: 119 | J4: =I4/Calculation!$B$2 -> 98.347107 | K4: 3 | L4: =K4*I4 -> 357 | M4: =K4*J4 -> 295.04132 | N4: =L4-M4 -> 61.958678 | O4: https://www.ikea.com/be/nl/p/trotten-bureau-beige-wit-s69434270/#content
A5: Fixed Assets | D5: Equity | H5: Chairs | I5: 129 | J5: =I5/Calculation!$B$2 -> 106.61157 | K5: 5 | L5: =K5*I5 -> 645 | M5: =K5*J5 -> 533.05785 | N5: =L5-M5 -> 111.94215 | O5: https://www.ikea.com/be/nl/p/langfjall-vergaderstoel-gunnared-beige-wit-s19252366/
A6: Inventory | B6: =M24 -> 3137.0496 | D6: Shareholders equity | E6: 55000 | H6: Coffee machine | I6: 579 | J6: =I6/Calculation!$B$2 -> 478.5124 | K6: 1 | L6: =K6*I6 -> 579 | M6: =K6*J6 -> 478.5124 | N6: =L6-M6 -> 100.4876 | O6: https://www.coolblue.be/en/product/841445/sage-barista-express-black-sesame.html
A7: Computers | B7: =M32 -> 3290.9091 | H7: Philips screens | I7: 169 | J7: =I7/Calculation!$B$2 -> 139.66942 | K7: 1 | L7: =K7*I7 -> 169 | M7: =K7*J7 -> 139.66942 | N7: =L7-M7 -> 29.330579 | O7: https://www.coolblue.be/product/780862/philips-273v7qdab.html
H8: Couch | I8: 249 | J8: =I8/Calculation!$B$2 -> 205.78512 | K8: 1 | L8: =K8*I8 -> 249 | M8: =K8*J8 -> 205.78512 | N8: =L8-M8 -> 43.214876 | O8: https://www.ikea.com/be/en/p/linanaes-2-seat-sofa-vissle-beige-40499974/
H9: Camera | I9: 680 | J9: =I9/Calculation!$B$2 -> 561.98347 | K9: 1 | L9: =K9*I9 -> 680 | M9: =K9*J9 -> 561.98347 | N9: =L9-M9 -> 118.01653 | O9: https://brookpad.be/en/products/nikon-d3500-w-af-p-dx-nikkor-18-55mm-f-3-5-5-6g-vr-black?variant=42807637704943&utm_source=google&utm_medium=organic&utm_campaign=EFLcomEN+USD&utm_content=Nikon+D3500+W%2F+AF-P+DX+NIKKOR+18-55mm+f%2F3.5-5.6G+VR+Black&shpxid=1e28a4c5-d65a-46e1-9d31-7e35482f671b
H10: Camera lights | I10: 84.99 | J10: =I10/Calculation!$B$2 -> 70.239669 | K10: 1 | L10: =K10*I10 -> 84.99 | M10: =K10*J10 -> 70.239669 | N10: =L10-M10 -> 14.750331 | O10: https://www.coolblue.be/product/891873/bresser-br-225b-led-daglichtset.html?cmt=c_a%2Ccid_16560080773%2Caid_132450828622%2Ctid_aud-1676514780854%3Apla-307831767538%2Cgn_g%2Cd_c&utm_source=google&utm_medium=cpc&utm_content=shopping&gclid=Cj0KCQjw-fmZBhDtARIsAH6H8qhq0EkYLz0AKdalF4ZwQkous3QulkCIob21pG_NnPzDibL1Q-rN1wcaAl4ZEALw_wcB
A11: Current Assets | H11: Cutlery | I11: 4.99 | J11: =I11/Calculation!$B$2 -> 4.1239669 | K11: 1 | L11: =K11*I11 -> 4.99 | M11: =K11*J11 -> 4.1239669 | N11: =L11-M11 -> 0.86603306 | O11: https://www.ikea.com/be/nl/p/mopsig-bestek-16-delig-00343003/
H12: Dishes
A13: VAT to Receive | B13: =N24+N32+N45 -> 1625.4912 | H13: Cups | I13: 3.99 | J13: =I13/Calculation!$B$2 -> 3.2975207 | K13: 5 | L13: =K13*I13 -> 19.95 | M13: =K13*J13 -> 16.487603 | N13: =L13-M13 -> 3.4623967 | O13: https://www.ikea.com/be/nl/p/vardera-koffiekop-en-schotel-60277463/
H14: Plates Set | I14: 29.99 | J14: =I14/Calculation!$B$2 -> 24.785124 | K14: 1 | L14: =K14*I14 -> 29.99 | M14: =K14*J14 -> 24.785124 | N14: =L14-M14 -> 5.204876 | O14: https://www.ikea.com/be/nl/p/godmiddag-servies-24-delig-wit-60479734/
A15: Startup Costs | B15: =M45 -> 1144.3802 | D15: Long Term Loan/Debt | H15: Printer | I15: 539 | J15: =I15/Calculation!$B$2 -> 445.45455 | K15: 1 | L15: =K15*I15 -> 539 | M15: =K15*J15 -> 445.45455 | N15: =L15-M15 -> 93.545455 | O15: https://www.coolblue.be/product/858209/hp-color-laserjet-pro-m283fdw-mfp.html?cmt=c_a%2Ccid_16731022239%2Caid_140337336372%2Ctid_pla-318416504858%2Cgn_g%2Cd_c&utm_source=google&utm_medium=cpc&utm_content=shopping&gclid=Cj0KCQjw-fmZBhDtARIsAH6H8qgySnNCidJA2Z_IlR0pnLnqiQAo3D8KXi57f7Jfe4LAnd5LnQh6igYaAhz-EALw_wcB
D16: 7.45% Bank loan 3 year | E16: 20000 | H16: Office phone | I16: 59.99 | J16: =I16/Calculation!$B$2 -> 49.578512 | K16: 1 | L16: =K16*I16 -> 59.99 | M16: =K16*J16 -> 49.578512 | N16: =L16-M16 -> 10.411488 | O16: https://productpine.com/nl/products/profoon-cordless-telephone-3-handsets?channable=027fcd6964003433353531303033353038393439c8&variant=43551003508949&utm_source=google&utm_medium=free_listing&utm_campaign=free_listing&utm_source=google&utm_medium=cpc&utm_campaign=18136423564&utm_content=&utm_term=&gclid=Cj0KCQjw-fmZBhDtARIsAH6H8qg1FQtZ10ktal2SoLqmyKKICqVHQmyzIq8RRXh1OBNyIP3YMYxxQeYaAv0MEALw_wcB
A17: Liquid Assets | H17: Decor
A18: Bank | B18: =E23-(B6+B7+B16+B13+B15+B14) -> 69784.17 | H18: Desk lights | I18: 9.99 | J18: =I18/Calculation!$B$2 -> 8.2561983 | K18: 3 | L18: =K18*I18 -> 29.97 | M18: =K18*J18 -> 24.768595 | N18: =L18-M18 -> 5.201405 | O18: https://www.ikea.com/be/nl/p/lovmanad-bureaulamp-zwart-50518439/
A19: Cash | B19: 0 | D19: Short Term Loan/Debt | H19: Plants | I19: 3.99 | J19: =I19/Calculation!$B$2 -> 3.2975207 | K19: 5 | L19: =K19*I19 -> 19.95 | M19: =K19*J19 -> 16.487603 | N19: =L19-M19 -> 3.4623967 | O19: https://www.ikea.com/be/nl/p/fejka-kunstplant-binnen-buiten-eikvaren-50493349/
D20: Accounts Payable (incl. VAT) | E20: =I32 -> 3982 | H20: Closet | I20: 179 | J20: =I20/Calculation!$B$2 -> 147.93388 | K20: 1 | L20: =K20*I20 -> 179 | M20: =K20*J20 -> 147.93388 | N20: =L20-M20 -> 31.066116 | O20: https://www.ikea.com/be/en/p/brimnes-wardrobe-with-3-doors-white-40407922/
H21: Storage closet | I21: 149 | J21: =I21/Calculation!$B$2 -> 123.1405 | K21: 1 | L21: =K21*I21 -> 149 | M21: =K21*J21 -> 123.1405 | N21: =L21-M21 -> 25.859504 | O21: https://www.ikea.com/be/nl/p/vihals-opbergmeubel-wit-90483268/
A23: Total | B23: =SUM(B6:B19) -> 78982 | D23: Total | E23: =SUM(E6:E22) -> 78982
H24: Total | I24: =SUM(I4:I21) -> 2989.93 | J24: =SUM(J4:J21) -> 2471.0165 | L24: =SUM(L4:L21) -> 3795.83 | M24: =SUM(M4:M21) -> 3137.0496 | N24: =SUM(N4:N21) -> 658.78041
H26: List computers | I26: Incl. VAT | J26: Excl. VAT | K26: Number | L26: Total incl. VAT | M26: Total excl. VAT | N26: Total VAT | O26: Reference url | P26: Additional notes
H27: Macbook Pro 13-inch | I27: 1849 | J27: =I27/Calculation!$B$2 -> 1528.0992 | K27: 1 | L27: =K27*I27 -> 1849 | M27: =K27*J27 -> 1528.0992 | N27: =L27-M27 -> 320.90083 | O27: https://www.apple.com/be-nl/shop/buy-mac/macbook-pro/13%E2%80%91inch-spacegrijs-apple-m2-chip-met-8-core-cpu-en-10-core-gpu-512gb
H28: iMac 24‑inch | I28: 2133 | J28: =I28/Calculation!$B$2 -> 1762.8099 | K28: 1 | L28: =K28*I28 -> 2133 | M28: =K28*J28 -> 1762.8099 | N28: =L28-M28 -> 370.19008 | O28: https://www.apple.com/be-nl/shop/buy-mac/imac/blauw-24%E2%80%91inch-8-core-cpu-8-core-gpu-8-gb-geheugen-512gb
H32: Total | I32: =SUM(I27:I28) -> 3982 | J32: =SUM(J27:J28) -> 3290.9091 | L32: =SUM(L27:L28) -> 3982 | M32: =SUM(M27:M28) -> 3290.9091 | N32: =SUM(N27:N28) -> 691.09091
H34: List Car(s) | I34: Incl. VAT | J34: Excl. VAT | K34: Number | L34: Total incl. VAT | M34: Total excl. VAT | N34: Total VAT | O34: Reference url | P34: Additional notes
H36: Total
H38: List Start-up Costs | I38: Incl. VAT | J38: Excl. VAT | K38: Number | L38: Total incl. VAT | M38: Total excl. VAT | N38: Total VAT | O38: Reference url | P38: Additional notes
H39: Ch of comm. Registration | I39: 70 | J39: 70 | K39: 1 | L39: =I39*K39 -> 70 | M39: =J39*K39 -> 70 | N39: =M39-L39 -> 0 | O39: https://www.lawyersbelgium.com/open-a-company-in-belgium
H40: Notary | I40: 1300 | J40: =I40/Calculation!B2 -> 1074.3802 | K40: 1 | L40: =I40*K40 -> 1300 | M40: =J40*K40 -> 1074.3802 | N40: =L40-M40 -> 225.61983 | O40: https://belgium.euresidence.me/company-registration-in-belgium/#:~:text=Notary%20and%20Ministry%20of%20Economy,statutory%20business%20plan%20are%20included.&text=VAT%20registration%2C%20if%20needed%2C%20100,EUR%20fee%20%2B%20EORI%20registration%20free.
H41: VAT registration fee | I41: 50 | J41: 50 | K41: 1 | L41: 50 | M41: 0 | N41: =I41 -> 50 | O41: https://www.lawyersbelgium.com/open-a-company-in-belgium
H45: Total | L45: =SUM(L39:L41) -> 1420 | M45: =SUM(M39:M41) -> 1144.3802 | N45: =SUM(N39:N41) -> 275.61983
H47: Repayment Schedule Bankloan | I47: Jan | J47: Feb | K47: March | L47: April | M47: May | N47: June | O47: July | P47: Aug | Q47: Sept | R47: Oct | S47: Nov | T47: Dec | X47: Jan
H48: Source: https://promo.ing.be/businesscredit/Simulation?product=BLO&LANG=EN
H49: Outstanding loan | I49: =E16 -> 20000 | J49: =I49-I50 -> 19444.444 | K49: =J49-J50 -> 18888.889 | L49: =K49-K50 -> 18333.333 | M49: =L49-L50 -> 17777.778 | N49: =M49-M50 -> 17222.222 | O49: =N49-N50 -> 16666.667 | P49: =O49-O50 -> 16111.111 | Q49: =P49-P50 -> 15555.556 | ... T49: =S49-S50 -> 13888.889 | U49: Outstanding 31/12 | V49: =T49-X49 -> 13333.333 | X49: =$I$49/$G$50 -> 555.55556
G50: 36 | H50: Repayments | I50: =$I$49/$G$50 -> 555.55556 | J50: =$I$49/$G$50 -> 555.55556 | K50: =$I$49/$G$50 -> 555.55556 | L50: =$I$49/$G$50 -> 555.55556 | M50: =$I$49/$G$50 -> 555.55556 | N50: =$I$49/$G$50 -> 555.55556 | O50: =$I$49/$G$50 -> 555.55556 | P50: =$I$49/$G$50 -> 555.55556 | ... T50: =$I$49/$G$50 -> 555.55556 | U50: Total | V50: =SUM(I50:T50) -> 6666.6667
G51: 0.0745 | H51: Interest | I51: =I49*$G$51/12 -> 124.16667 | J51: =J49*$G$51/12 -> 120.71759 | K51: =K49*$G$51/12 -> 117.26852 | L51: =L49*$G$51/12 -> 113.81944 | M51: =M49*$G$51/12 -> 110.37037 | N51: =N49*$G$51/12 -> 106.9213 | O51: =O49*$G$51/12 -> 103.47222 | P51: =P49*$G$51/12 -> 100.02315 | ... T51: =T49*$G$51/12 -> 86.226852 | U51: Total | V51: =SUM(I51:T51) -> 1262.3611
H53: Interest per year | I53: =SUM(I51:T51) -> 1262.3611

Sheet Balances
A1: Opening Balance
C2: Balance per Januari 1st year 2023
A3: Debet | F3: Credit
A5: Fixed Assets (exc. VAT) | D5: Equity
A6: ='inv+fin. budget'!A6 -> Inventory | B6: ='inv+fin. budget'!B6 -> 3137.0496 | D6: ='inv+fin. budget'!D6 -> Shareholders equity | E6: ='inv+fin. budget'!E6 -> 55000
A7: ='inv+fin. budget'!A7 -> Computers | B7: ='inv+fin. budget'!B7 -> 3290.9091
A11: Current Assets
A12: VAT to recieve | B12: ='inv+fin. budget'!B13 -> 1625.4912
A13: Start up costs | B13: ='inv+fin. budget'!B15 -> 1144.3802 | D13: Long Term Loan/Debt
D14: ='inv+fin. budget'!D16 -> 7.45% Bank loan 3 year | E14: ='inv+fin. budget'!E16 -> 20000
A15: Liquid Assets
A16: ='inv+fin. budget'!A18 -> Bank | B16: ='inv+fin. budget'!B18 -> 69784.17
A17: ='inv+fin. budget'!A19 -> Cash | B17: ='inv+fin. budget'!B19 -> 0 | D17: Short Term Loan/Debt
D18: ='inv+fin. budget'!D20 -> Accounts Payable (incl. VAT) | E18: ='inv+fin. budget'!E20 -> 3982
A21: Total | B21: ='inv+fin. budget'!B23 -> 78982 | D21: Total | E21: ='inv+fin. budget'!E23 -> 78982
A26: Closing Balance
C27: Balance per December 31st, year 2023
A28: Debet | F28: Credit
A30: Fixed Assets | D30: Equity
A31: =A6 -> Inventory | B31: =B6-'Cost price or Hourly rate'!G23 -> 2512.0854 | D31: Shareholders equity | E31: =E6 -> 55000
A32: Computers | B32: ='inv+fin. budget'!M32-('Cost price or Hourly rate'!F19+'Cost price or Hourly rate'!F20) -> 2872.7273 | D32: Undivided Profit | E32: ='P&L'!B43 -> 1752.9997
F33: =E31+E32 -> 56753
A36: Current Assets
A37: Accounts Receivable | B37: =('P&L'!M5+'P&L'!M6+'P&L'!M7)*Calculation!B2 -> 23110.928
A38: VAT to receive | D38: Long Term Loan/Debt
A39: Startup costs | B39: =B13-'Cost price or Hourly rate'!F21 -> 0 | D39: Bank loan outstanding | E39: ='inv+fin. budget'!E16-'inv+fin. budget'!V50 -> 13333.333
A41: Liquid Assets
A42: Bank | B42: ='Cash Flow'!E27 -> 45782.692 | D42: Short Term Loan/Debt
A43: Cash | D43: Profit tax to pay | E43: ='P&L'!B41 -> 584.33324
D45: VAT to pay | E45: ='Cash Flow'!E34 -> 3607.7658
A46: Total | B46: =SUM(B31:B43) -> 74278.432 | D46: Total | E46: =F33+E39+E43+E45 -> 74278.432

Sheet Cost price or Hourly rate
A1: Calculation Cost Price or Hourly Rate
A2: Depreciations | B2: Purchase Amount excl. VAT | C2: Residual Value | D2: Depreciation Amount | E2: Life of asset (Number of years) | F2: Depreciation p/y | G2: Notes
A3: ='inv+fin. budget'!H4 -> Desks | B3: ='inv+fin. budget'!M4 -> 295.04132 | C3: =30*'inv+fin. budget'!K4 -> 90 | D3: =B3-C3 -> 205.04132 | E3: 4 | F3: =D3/E3 -> 51.260331
A4: ='inv+fin. budget'!H5 -> Chairs | B4: ='inv+fin. budget'!M5 -> 533.05785 | C4: =45*'inv+fin. budget'!K5 -> 225 | D4: =B4-C4 -> 308.05785 | E4: 7 | F4: =D4/E4 -> 44.008264
A5: ='inv+fin. budget'!H6 -> Coffee machine | B5: ='inv+fin. budget'!M6 -> 478.5124 | C5: =100*'inv+fin. budget'!K6 -> 100 | D5: =B5-C5 -> 378.5124 | E5: 2 | F5: =D5/E5 -> 189.2562
A6: ='inv+fin. budget'!H7 -> Philips screens | B6: ='inv+fin. budget'!M7 -> 139.66942 | C6: =50*'inv+fin. budget'!K7 -> 50 | D6: =B6-C6 -> 89.669421 | E6: 3 | F6: =D6/E6 -> 29.889807
A7: ='inv+fin. budget'!H8 -> Couch | B7: ='inv+fin. budget'!M8 -> 205.78512 | C7: =50*'inv+fin. budget'!K8 -> 50 | D7: =B7-C7 -> 155.78512 | E7: 10 | F7: =D7/E7 -> 15.578512
A8: ='inv+fin. budget'!H9 -> Camera | B8: ='inv+fin. budget'!M9 -> 561.98347 | C8: =150*'inv+fin. budget'!K9 -> 150 | D8: =B8-C8 -> 411.98347 | E8: 3 | F8: =D8/E8 -> 137.32782
A9: ='inv+fin. budget'!H10 -> Camera lights | B9: ='inv+fin. budget'!M10 -> 70.239669 | C9: =30*'inv+fin. budget'!K10 -> 30 | D9: =B9-C9 -> 40.239669 | E9: 2 | F9: =D9/E9 -> 20.119835
A10: ='inv+fin. budget'!H11 -> Cutlery | B10: ='inv+fin. budget'!M11 -> 4.1239669 | C10: =1*'inv+fin. budget'!K11 -> 1 | D10: =B10-C10 -> 3.1239669 | E10: 4 | F10: =D10/E10 -> 0.78099174
A11: ='inv+fin. budget'!H13 -> Cups | B11: ='inv+fin. budget'!M13 -> 16.487603 | C11: =1*'inv+fin. budget'!K13 -> 5 | D11: =B11-C11 -> 11.487603 | E11: 2 | F11: =D11/E11 -> 5.7438017
A12: ='inv+fin. budget'!H14 -> Plates Set | B12: ='inv+fin. budget'!M14 -> 24.785124 | C12: =5*'inv+fin. budget'!K14 -> 5 | D12: =B12-C12 -> 19.785124 | E12: 2 | F12: =D12/E12 -> 9.892562
A13: ='inv+fin. budget'!H15 -> Printer | B13: ='inv+fin. budget'!M15 -> 445.45455 | C13: =200*'inv+fin. budget'!K15 -> 200 | D13: =B13-C13 -> 245.45455 | E13: 5 | F13: =D13/E13 -> 49.090909
A14: ='inv+fin. budget'!H16 -> Office phone | B14: ='inv+fin. budget'!M16 -> 49.578512 | C14: 10 | D14: =B14-C14 -> 39.578512 | E14: 3 | F14: =D14/E14 -> 13.192837
A15: ='inv+fin. budget'!H18 -> Desk lights | B15: ='inv+fin. budget'!M18 -> 24.768595 | C15: =2*'inv+fin. budget'!K18 -> 6 | D15: =B15-C15 -> 18.768595 | E15: 3 | F15: =D15/E15 -> 6.2561983
A16: ='inv+fin. budget'!H19 -> Plants | B16: ='inv+fin. budget'!M19 -> 16.487603 | C16: =1*'inv+fin. budget'!K19 -> 5 | D16: =B16-C16 -> 11.487603 | E16: 5 | F16: =D16/E16 -> 2.2975207
A17: ='inv+fin. budget'!H20 -> Closet | B17: ='inv+fin. budget'!M20 -> 147.93388 | C17: =50*'inv+fin. budget'!K20 -> 50 | D17: =B17-C17 -> 97.933884 | E17: 4 | F17: =D17/E17 -> 24.483471
A18: ='inv+fin. budget'!H21 -> Storage closet | B18: ='inv+fin. budget'!M21 -> 123.1405 | C18: =20*'inv+fin. budget'!K21 -> 20 | D18: =B18-C18 -> 103.1405 | E18: 4 | F18: =D18/E18 -> 25.785124
A19: ='inv+fin. budget'!H27 -> Macbook Pro 13-inch | B19: ='inv+fin. budget'!M27 -> 1528.0992 | C19: =600*'inv+fin. budget'!K27 -> 600 | D19: =B19-C19 -> 928.09917 | E19: 5 | F19: =D19/E19 -> 185.61983
A20: ='inv+fin. budget'!H28 -> iMac 24‑inch | B20: ='inv+fin. budget'!M28 -> 1762.8099 | C20: =600*'inv+fin. budget'!K28 -> 600 | D20: =B20-C20 -> 1162.8099 | E20: 5 | F20: =D20/E20 -> 232.56198
A21: ='inv+fin. budget'!A15 -> Startup Costs | B21: ='inv+fin. budget'!M45 -> 1144.3802 | C21: 0 | D21: =B21-C21 -> 1144.3802 | E21: 1 | F21: =D21/E21 -> 1144.3802
G22: Total without computers
A23: Total | F23: =SUM(F3:F21) -> 2187.5262 | G23: =SUM(F3:F18) -> 624.96419
A25: Business costs | B25: Amount per month excl. VAT | C25: Costs per month/year | D25: Costs per year | E25: Source | F25: Add notes
A26: Office Rent | B26: 700 | C26: Month | D26: =B26*12 -> 8400 | E26: https://www.instantoffices.com/en/be/available-office-space/brussels/rue-d-arlon-71888
A27: Subscription: Adobe | B27: 73.49 | C27: Month | D27: =B27*12 -> 881.88 | E27: https://www.adobe.com/be_nl/creativecloud/business-plans.html?plan=team&step=2
A28: Subscription: Zoom | B28: 13.99 | C28: Month | D28: =B28*12 -> 167.88 | E28: https://zoom.us/buy
A29: Subscription: Landline office | B29: 10 | C29: Month | D29: =B29*12 -> 120 | E29: https://callmepower.be/nl/telecom/gids/vergelijken/vaste-telefoon
A30: Energy & Gas | B30: 150 | C30: Month | D30: =B30*12 -> 1800 | E30: https://www.boltenergie.be/nl/onze-producenten/jouw-persoonlijk-aanbod
A31: Interest | B31: ='inv+fin. budget'!I53 -> 1262.3611 | C31: Year | D31: =B31 -> 1262.3611
A36: Total | B36: =SUM(B26:B31) -> 2209.8411 | D36: =SUM(D26:D31) -> 12632.121
A37: Salaries or Owners fee | B37: FTE Monthly | C37: € per Month | D37: Hours per week | E37: Vacation Pay 8% | F37: Employers costs 16% | G37: Total € per Year
A38: Manager | B38: 3500 | C38: =B38/Calculation!$B$11*'Cost price or Hourly rate'!D38 -> 3500 | D38: 40 | E38: =C38*Calculation!B7 -> 280 | F38: =C38*Calculation!B8 -> 560 | G38: =C38*12 -> 42000
A39: Intern Assistant (Partime) | B39: 400 | C39: =B39/Calculation!$B$11*'Cost price or Hourly rate'!D39 -> 300 | D39: 30 | E39: =C39*Calculation!B7 -> 24 | F39: =C39*Calculation!B8 -> 48 | G39: =C39*12 -> 3600
A45: Total | B45: =SUM(B38:B40) -> 3900 | C45: =SUM(C38:C40) -> 3800 | E45: =SUM(E38:E40) -> 304 | F45: =SUM(F38:F40) -> 608 | G45: =SUM(G38:G39) -> 45600
A48: Total Constant costs
A50: Depreciations per year | B50: =F23 -> 2187.5262
A51: Business Costs | B51: =D36 -> 12632.121
A52: Salaries | B52: =G45 -> 45600
A55: Total | B55: =SUM(B50:B52) -> 60419.647
...

Sheet P&L
A1: Profit & Loss Budget | B1: Year 1
C2: Quarter I | F2: Quarter II | I2: Quarter III | L2: Quarter IV | N2: Total | O2: Extra Toelichting
A3: Month | B3: January | C3: February | D3: March | E3: April | F3: May | G3: June | H3: July | I3: August | J3: September | K3: October | L3: November | M3: December
A4: Revenue
A5: ='Cost price or Hourly rate'!A74 -> Designer | B5: ='Cost price or Hourly rate'!$K$61*'Cost price or Hourly rate'!B74 -> 0 | C5: ='Cost price or Hourly rate'!$K$61*'Cost price or Hourly rate'!C74 -> 790.07034 | D5: ='Cost price or Hourly rate'!$K$61*'Cost price or Hourly rate'!D74 -> 1580.1407 | E5: ='Cost price or Hourly rate'!$K$61*'Cost price or Hourly rate'!E74 -> 3397.3025 | F5: ='Cost price or Hourly rate'!$K$61*'Cost price or Hourly rate'!F74 -> 5372.4783 | G5: ='Cost price or Hourly rate'!$K$61*'Cost price or Hourly rate'!G74 -> 5214.4642 | H5: ='Cost price or Hourly rate'!$K$61*'Cost price or Hourly rate'!H74 -> 5293.4713 | I5: ='Cost price or Hourly rate'!$K$61*'Cost price or Hourly rate'!I74 -> 6083.5416 | ... N5: ='Cost price or Hourly rate'!$K$61*'Cost price or Hourly rate'!N74 -> 51591.593
A6: ='Cost price or Hourly rate'!A75 -> PR Specialist | B6: ='Cost price or Hourly rate'!$K$62*'Cost price or Hourly rate'!B75 -> 0 | C6: ='Cost price or Hourly rate'!$K$62*'Cost price or Hourly rate'!C75 -> 1261.4688 | D6: ='Cost price or Hourly rate'!$K$62*'Cost price or Hourly rate'!D75 -> 2522.9375 | E6: ='Cost price or Hourly rate'!$K$62*'Cost price or Hourly rate'!E75 -> 7484.7147 | F6: ='Cost price or Hourly rate'!$K$62*'Cost price or Hourly rate'!F75 -> 5550.4626 | G6: ='Cost price or Hourly rate'!$K$62*'Cost price or Hourly rate'!G75 -> 4373.0917 | H6: ='Cost price or Hourly rate'!$K$62*'Cost price or Hourly rate'!H75 -> 8325.6939 | I6: ='Cost price or Hourly rate'!$K$62*'Cost price or Hourly rate'!I75 -> 6643.7355 | ... N6: ='Cost price or Hourly rate'!$K$62*'Cost price or Hourly rate'!N75 -> 67362.432
A7: ='Cost price or Hourly rate'!A76 -> Social Media Manager | B7: ='Cost price or Hourly rate'!$K$63*'Cost price or Hourly rate'!B76 -> 0 | C7: ='Cost price or Hourly rate'!$K$63*'Cost price or Hourly rate'!C76 -> 1780.6438 | D7: ='Cost price or Hourly rate'!$K$63*'Cost price or Hourly rate'!D76 -> 4451.6094 | E7: ='Cost price or Hourly rate'!$K$63*'Cost price or Hourly rate'!E76 -> 7923.8648 | F7: ='Cost price or Hourly rate'!$K$63*'Cost price or Hourly rate'!F76 -> 9793.5408 | G7: ='Cost price or Hourly rate'!$K$63*'Cost price or Hourly rate'!G76 -> 12909.667 | H7: ='Cost price or Hourly rate'!$K$63*'Cost price or Hourly rate'!H76 -> 11574.185 | I7: ='Cost price or Hourly rate'!$K$63*'Cost price or Hourly rate'!I76 -> 11485.152 | ... N7: ='Cost price or Hourly rate'!$K$63*'Cost price or Hourly rate'!N76 -> 100695.41
A9: Total | B9: =SUM(B5:B7) -> 0 | C9: =SUM(C5:C7) -> 3832.1829 | D9: =SUM(D5:D7) -> 8554.6877 | E9: =SUM(E5:E7) -> 18805.882 | F9: =SUM(F5:F7) -> 20716.482 | G9: =SUM(G5:G7) -> 22497.223 | H9: =SUM(H5:H7) -> 25193.35 | I9: =SUM(I5:I7) -> 24212.429 | ... N9: =SUM(N5:N7) -> 219649.43
A10: Variable costs
A11: ='Cost price or Hourly rate'!A61 -> PR Specialist | B11: ='Cost price or Hourly rate'!B74*'Cost price or Hourly rate'!$I$61 -> 0 | C11: ='Cost price or Hourly rate'!C74*'Cost price or Hourly rate'!$I$61 -> 564.33596 | D11: ='Cost price or Hourly rate'!D74*'Cost price or Hourly rate'!$I$61 -> 1128.6719 | E11: ='Cost price or Hourly rate'!E74*'Cost price or Hourly rate'!$I$61 -> 2426.6446 | F11: ='Cost price or Hourly rate'!F74*'Cost price or Hourly rate'!$I$61 -> 3837.4845 | G11: ='Cost price or Hourly rate'!G74*'Cost price or Hourly rate'!$I$61 -> 3724.6173 | H11: ='Cost price or Hourly rate'!H74*'Cost price or Hourly rate'!$I$61 -> 3781.0509 | I11: ='Cost price or Hourly rate'!I74*'Cost price or Hourly rate'!$I$61 -> 4345.3869 | ... N11: ='Cost price or Hourly rate'!N74*'Cost price or Hourly rate'!$I$61 -> 36851.138
A12: ='Cost price or Hourly rate'!A62 -> Designer | B12: ='Cost price or Hourly rate'!B75*'Cost price or Hourly rate'!$I$62 -> 0 | C12: ='Cost price or Hourly rate'!C75*'Cost price or Hourly rate'!$I$62 -> 901.04912 | D12: ='Cost price or Hourly rate'!D75*'Cost price or Hourly rate'!$I$62 -> 1802.0982 | E12: ='Cost price or Hourly rate'!E75*'Cost price or Hourly rate'!$I$62 -> 5346.2248 | F12: ='Cost price or Hourly rate'!F75*'Cost price or Hourly rate'!$I$62 -> 3964.6161 | G12: ='Cost price or Hourly rate'!G75*'Cost price or Hourly rate'!$I$62 -> 3123.6369 | H12: ='Cost price or Hourly rate'!H75*'Cost price or Hourly rate'!$I$62 -> 5946.9242 | I12: ='Cost price or Hourly rate'!I75*'Cost price or Hourly rate'!$I$62 -> 4745.5254 | ... N12: ='Cost price or Hourly rate'!N75*'Cost price or Hourly rate'!$I$62 -> 48116.023
A13: ='Cost price or Hourly rate'!A63 -> Social Media Manager | B13: ='Cost price or Hourly rate'!B76*'Cost price or Hourly rate'!$I$63 -> 0 | C13: ='Cost price or Hourly rate'!C76*'Cost price or Hourly rate'!$I$63 -> 1271.8884 | D13: ='Cost price or Hourly rate'!D76*'Cost price or Hourly rate'!$I$63 -> 3179.721 | E13: ='Cost price or Hourly rate'!E76*'Cost price or Hourly rate'!$I$63 -> 5659.9034 | F13: ='Cost price or Hourly rate'!F76*'Cost price or Hourly rate'!$I$63 -> 6995.3863 | G13: ='Cost price or Hourly rate'!G76*'Cost price or Hourly rate'!$I$63 -> 9221.191 | H13: ='Cost price or Hourly rate'!H76*'Cost price or Hourly rate'!$I$63 -> 8267.2747 | I13: ='Cost price or Hourly rate'!I76*'Cost price or Hourly rate'!$I$63 -> 8203.6803 | ... N13: ='Cost price or Hourly rate'!N76*'Cost price or Hourly rate'!$I$63 -> 71925.29
A15: Total | B15: =SUM(B11:B13) -> 0 | C15: =SUM(C11:C13) -> 2737.2735 | D15: =SUM(D11:D13) -> 6110.4912 | E15: =SUM(E11:E13) -> 13432.773 | F15: =SUM(F11:F13) -> 14797.487 | G15: =SUM(G11:G13) -> 16069.445 | H15: =SUM(H11:H13) -> 17995.25 | I15: =SUM(I11:I13) -> 17294.592 | ... N15: =SUM(N11:N13) -> 156892.45
A17: Brute Margin | B17: =B9-B15 -> 0 | C17: =C9-C15 -> 1094.9094 | D17: =D9-D15 -> 2444.1965 | E17: =E9-E15 -> 5373.1091 | F17: =F9-F15 -> 5918.9948 | G17: =G9-G15 -> 6427.7781 | H17: =H9-H15 -> 7198.0999 | I17: =I9-I15 -> 6917.837 | ... N17: =N9-N15 -> 62756.98
A19: Month | B19: January | C19: February | D19: March | E19: April | F19: May | G19: June | H19: July | I19: August | J19: September | K19: October | L19: November | M19: December
A20: Costs
A21: ='Cost price or Hourly rate'!A50 -> Depreciations per year | B21: =$N21/12 -> 182.29385 | C21: =$N21/12 -> 182.29385 | D21: =$N21/12 -> 182.29385 | E21: =$N21/12 -> 182.29385 | F21: =$N21/12 -> 182.29385 | G21: =$N21/12 -> 182.29385 | H21: =$N21/12 -> 182.29385 | I21: =$N21/12 -> 182.29385 | ... M21: =$N21/12 -> 182.29385 | N21: ='Cost price or Hourly rate'!F23 -> 2187.5262
A22: Salaries | B22: =$N22/12 -> 3800 | C22: =$N22/12 -> 3800 | D22: =$N22/12 -> 3800 | E22: =$N22/12 -> 3800 | F22: =$N22/12 -> 3800 | G22: =$N22/12 -> 3800 | H22: =$N22/12 -> 3800 | I22: =$N22/12 -> 3800 | ... M22: =$N22/12 -> 3800 | N22: ='Cost price or Hourly rate'!G45 -> 45600
A23: ='Cost price or Hourly rate'!A26 -> Office Rent | B23: ='Cost price or Hourly rate'!$B$26 -> 700 | C23: ='Cost price or Hourly rate'!$B$26 -> 700 | D23: ='Cost price or Hourly rate'!$B$26 -> 700 | E23: ='Cost price or Hourly rate'!$B$26 -> 700 | F23: ='Cost price or Hourly rate'!$B$26 -> 700 | G23: ='Cost price or Hourly rate'!$B$26 -> 700 | H23: ='Cost price or Hourly rate'!$B$26 -> 700 | I23: ='Cost price or Hourly rate'!$B$26 -> 700 | ... M23: ='Cost price or Hourly rate'!$B$26 -> 700 | N23: ='Cost price or Hourly rate'!D26 -> 8400
A24: ='Cost price or Hourly rate'!A27 -> Subscription: Adobe | B24: ='Cost price or Hourly rate'!$B$27 -> 73.49 | C24: ='Cost price or Hourly rate'!$B$27 -> 73.49 | D24: ='Cost price or Hourly rate'!$B$27 -> 73.49 | E24: ='Cost price or Hourly rate'!$B$27 -> 73.49 | F24: ='Cost price or Hourly rate'!$B$27 -> 73.49 | G24: ='Cost price or Hourly rate'!$B$27 -> 73.49 | H24: ='Cost price or Hourly rate'!$B$27 -> 73.49 | I24: ='Cost price or Hourly rate'!$B$27 -> 73.49 | ... M24: ='Cost price or Hourly rate'!$B$27 -> 73.49 | N24: ='Cost price or Hourly rate'!D27 -> 881.88
A25: ='Cost price or Hourly rate'!A28 -> Subscription: Zoom | B25: ='Cost price or Hourly rate'!$B$28 -> 13.99 | C25: ='Cost price or Hourly rate'!$B$28 -> 13.99 | D25: ='Cost price or Hourly rate'!$B$28 -> 13.99 | E25: ='Cost price or Hourly rate'!$B$28 -> 13.99 | F25: ='Cost price or Hourly rate'!$B$28 -> 13.99 | G25: ='Cost price or Hourly rate'!$B$28 -> 13.99 | H25: ='Cost price or Hourly rate'!$B$28 -> 13.99 | I25: ='Cost price or Hourly rate'!$B$28 -> 13.99 | ... M25: ='Cost price or Hourly rate'!$B$28 -> 13.99 | N25: ='Cost price or Hourly rate'!D28 -> 167.88
A26: ='Cost price or Hourly rate'!A29 -> Subscription: Landline office | B26: ='Cost price or Hourly rate'!$B$29 -> 10 | C26: ='Cost price or Hourly rate'!$B$29 -> 10 | D26: ='Cost price or Hourly rate'!$B$29 -> 10 | E26: ='Cost price or Hourly rate'!$B$29 -> 10 | F26: ='Cost price or Hourly rate'!$B$29 -> 10 | G26: ='Cost price or Hourly rate'!$B$29 -> 10 | H26: ='Cost price or Hourly rate'!$B$29 -> 10 | I26: ='Cost price or Hourly rate'!$B$29 -> 10 | ... M26: ='Cost price or Hourly rate'!$B$29 -> 10 | N26: ='Cost price or Hourly rate'!D29 -> 120
A27: ='Cost price or Hourly rate'!A30 -> Energy & Gas | B27: ='Cost price or Hourly rate'!$B$30 -> 150 | C27: ='Cost price or Hourly rate'!$B$30 -> 150 | D27: ='Cost price or Hourly rate'!$B$30 -> 150 | E27: ='Cost price or Hourly rate'!$B$30 -> 150 | F27: ='Cost price or Hourly rate'!$B$30 -> 150 | G27: ='Cost price or Hourly rate'!$B$30 -> 150 | H27: ='Cost price or Hourly rate'!$B$30 -> 150 | I27: ='Cost price or Hourly rate'!$B$30 -> 150 | ... M27: ='Cost price or Hourly rate'!$B$30 -> 150 | N27: ='Cost price or Hourly rate'!D30 -> 1800
A28: ='Cost price or Hourly rate'!A31 -> Interest | B28: ='inv+fin. budget'!I51 -> 124.16667 | C28: ='inv+fin. budget'!J51 -> 120.71759 | D28: ='inv+fin. budget'!K51 -> 117.26852 | E28: ='inv+fin. budget'!L51 -> 113.81944 | F28: ='inv+fin. budget'!M51 -> 110.37037 | G28: ='inv+fin. budget'!N51 -> 106.9213 | H28: ='inv+fin. budget'!O51 -> 103.47222 | I28: ='inv+fin. budget'!P51 -> 100.02315 | ... M28: ='inv+fin. budget'!T51 -> 86.226852 | N28: ='inv+fin. budget'!V51 -> 1262.3611
A30: Total | B30: =SUM(B21:B28) -> 5053.9405 | C30: =SUM(C21:C28) -> 5050.4914 | D30: =SUM(D21:D28) -> 5047.0424 | E30: =SUM(E21:E28) -> 5043.5933 | F30: =SUM(F21:F28) -> 5040.1442 | G30: =SUM(G21:G28) -> 5036.6951 | H30: =SUM(H21:H28) -> 5033.2461 | I30: =SUM(I21:I28) -> 5029.797 | ... N30: =SUM(N21:N28) -> 60419.647
A34: Net Profit before Tax | B34: =B17-B30 -> -5053.9405 | C34: =C17-C30 -> -3955.582 | D34: =D17-D30 -> -2602.8459 | E34: =E17-E30 -> 329.51584 | F34: =F17-F30 -> 878.85054 | G34: =G17-G30 -> 1391.083 | H34: =H17-H30 -> 2164.8538 | I34: =I17-I30 -> 1888.04 | ... N34: =N17-N30 -> 2337.333
A36: Year Profit | B36: =N34 -> 2337.333
A40: Taxes | B40: 0.25 | C40: Source | D40: Notes
A41: Profit tax | B41: =B36*B40 -> 584.33324 | C41: https://finance.belgium.be/en/enterprises/corporation-tax/corporate-income-tax-return
A43: Profit after tax | B43: =B36-B41 -> 1752.9997

Sheet Cash Flow
A1: Cash Flow Forecast | B1: Year I
B2: Quarter I | C2: Quarter II | D2: Quarter III | E2: Quarter IV | G2: Notes
A3: Bank begin | B3: =Balances!B16 -> 69784.17 | C3: =B27 -> 44490.635 | D3: =C27 -> 32077.794 | E3: =D27 -> 34186.037
A4: Receipts
A5: ='Cost price or Hourly rate'!A61 -> PR Specialist | B5: =('P&L'!B5+'P&L'!C5)*Calculation!B2 -> 955.98511 | C5: =('P&L'!D5+'P&L'!E5+'P&L'!F5)*Calculation!B2 -> 12523.405 | D5: =('P&L'!G5+'P&L'!H5+'P&L'!I5)*Calculation!B2 -> 20075.687 | E5: =('P&L'!J5+'P&L'!K5+'P&L'!L5)*Calculation!B2 -> 26289.591 | G5: Payment term (30 days)
A6: ='Cost price or Hourly rate'!A62 -> Designer | B6: =('P&L'!B6+'P&L'!C6)*Calculation!B2 -> 1526.3772 | C6: =('P&L'!D6+'P&L'!E6+'P&L'!F6)*Calculation!B2 -> 18825.319 | D6: =('P&L'!G6+'P&L'!H6+'P&L'!I6)*Calculation!B2 -> 23404.45 | E6: =('P&L'!J6+'P&L'!K6+'P&L'!L6)*Calculation!B2 -> 27780.065 | G6: Payment term (30 days)
A7: ='Cost price or Hourly rate'!A63 -> Social Media Manager | B7: =('P&L'!B7+'P&L'!C7)*Calculation!B2 -> 2154.579 | C7: =('P&L'!D7+'P&L'!E7+'P&L'!F7)*Calculation!B2 -> 26824.508 | D7: =('P&L'!G7+'P&L'!H7+'P&L'!I7)*Calculation!B2 -> 43522.495 | E7: =('P&L'!J7+'P&L'!K7+'P&L'!L7)*Calculation!B2 -> 38782.421 | G7: Payment term (30 days)
A8: VAT to receive | B8: ='inv+fin. budget'!B13 -> 1625.4912
A10: Total incoming | B10: =SUM(B5:B9) -> 6262.4324 | C10: =SUM(C5:C9) -> 58173.232 | D10: =SUM(D5:D9) -> 87002.633 | E10: =SUM(E5:E9) -> 92852.077
A12: Spending
A13: Variable Costs | B13: =('P&L'!B15+'P&L'!C15+'P&L'!D15)*Calculation!B2 -> 10705.795 | C13: =('P&L'!E15+'P&L'!F15+'P&L'!G15)*Calculation!B2 -> 53602.643 | D13: =('P&L'!H15+'P&L'!I15+'P&L'!J15)*Calculation!B2 -> 64964.039 | E13: =('P&L'!K15+'P&L'!L15+'P&L'!M15)*Calculation!B2 -> 60567.388 | G13: VAT
A14: ='P&L'!A22 -> Salaries | B14: ='P&L'!B22+'P&L'!C22+'P&L'!D22 -> 11400 | C14: ='P&L'!E22+'P&L'!F22+'P&L'!G22 -> 11400 | D14: ='P&L'!H22+'P&L'!I22+'P&L'!J22 -> 11400 | E14: ='P&L'!K22+'P&L'!L22+'P&L'!M22 -> 11400 | G14: NO VAT
A15: ='P&L'!A23 -> Office Rent | B15: =('P&L'!B23+'P&L'!C23+'P&L'!D23)*Calculation!B2 -> 2541 | C15: =('P&L'!E23+'P&L'!F23+'P&L'!G23)*Calculation!B2 -> 2541 | D15: =('P&L'!H23+'P&L'!I23+'P&L'!J23)*Calculation!B2 -> 2541 | E15: =('P&L'!K23+'P&L'!L23+'P&L'!M23)*Calculation!B2 -> 2541 | G15: VAT
A16: ='P&L'!A24 -> Subscription: Adobe | B16: =('P&L'!B24+'P&L'!C24+'P&L'!D24)*Calculation!B2 -> 266.7687 | C16: =('P&L'!E24+'P&L'!F24+'P&L'!G24)*Calculation!B2 -> 266.7687 | D16: =('P&L'!H24+'P&L'!I24+'P&L'!J24)*Calculation!B2 -> 266.7687 | E16: =('P&L'!K24+'P&L'!L24+'P&L'!M24)*Calculation!B2 -> 266.7687 | G16: VAT
A17: ='P&L'!A25 -> Subscription: Zoom | B17: =('P&L'!B25+'P&L'!C25+'P&L'!D25)*Calculation!B2 -> 50.7837 | C17: =('P&L'!E25+'P&L'!F25+'P&L'!G25)*Calculation!B2 -> 50.7837 | D17: =('P&L'!H25+'P&L'!I25+'P&L'!J25)*Calculation!B2 -> 50.7837 | E17: =('P&L'!K25+'P&L'!L25+'P&L'!M25)*Calculation!B2 -> 50.7837 | G17: VAT
A18: ='P&L'!A26 -> Subscription: Landline office | B18: =('P&L'!B26+'P&L'!C26+'P&L'!D26)*Calculation!B2 -> 36.3 | C18: =('P&L'!E26+'P&L'!F26+'P&L'!G26)*Calculation!B2 -> 36.3 | D18: =('P&L'!H26+'P&L'!I26+'P&L'!J26)*Calculation!B2 -> 36.3 | E18: =('P&L'!K26+'P&L'!L26+'P&L'!M26)*Calculation!B2 -> 36.3 | G18: VAT
A19: ='P&L'!A27 -> Energy & Gas | B19: =('P&L'!B27+'P&L'!C27+'P&L'!D27)*Calculation!B2 -> 544.5 | C19: =('P&L'!E27+'P&L'!F27+'P&L'!G27)*Calculation!B2 -> 544.5 | D19: =('P&L'!H27+'P&L'!I27+'P&L'!J27)*Calculation!B2 -> 544.5 | E19: =('P&L'!K27+'P&L'!L27+'P&L'!M27)*Calculation!B2 -> 544.5 | G19: VAT
A20: ='P&L'!A28 -> Interest | B20: ='P&L'!B28+'P&L'!C28+'P&L'!D28 -> 362.15278 | C20: ='P&L'!E28+'P&L'!F28+'P&L'!G28 -> 331.11111 | D20: ='P&L'!H28+'P&L'!I28+'P&L'!J28 -> 300.06944 | E20: ='P&L'!K28+'P&L'!L28+'P&L'!M28 -> 269.02778 | G20: NO VAT
A21: Repayments | B21: ='inv+fin. budget'!I50+'inv+fin. budget'!J50+'inv+fin. budget'!K50 -> 1666.6667 | C21: =('inv+fin. budget'!L50+'inv+fin. budget'!M50+'inv+fin. budget'!N50) -> 1666.6667 | D21: =('inv+fin. budget'!O50+'inv+fin. budget'!P50+'inv+fin. budget'!Q50) -> 1666.6667 | E21: =('inv+fin. budget'!R50+'inv+fin. budget'!S50+'inv+fin. budget'!T50) -> 1666.6667 | G21: NO VAT
A22: Accounts Payable | B22: ='inv+fin. budget'!E20 -> 3982 | G22: NO VAT
A23: VAT to pay | C23: =B34 -> 146.29983 | D23: =C34 -> 3124.2628 | E23: =D34 -> 3912.9878
A26: Total spending | B26: =SUM(B13:B25) -> 31555.967 | C26: =SUM(C13:C25) -> 70586.073 | D26: =SUM(D13:D25) -> 84894.39 | E26: =SUM(E13:E25) -> 81255.423
A27: Bank end | B27: =B3+B10-B26 -> 44490.635 | C27: =C3+C10-C26 -> 32077.794 | D27: =D3+D10-D26 -> 34186.037 | E27: =E3+E10-E26 -> 45782.692
A31: VAT | B31: Quarter I | C31: Quarter II | D31: Quarter III | E31: Quarter IV
A32: VAT to pay = VAT received | B32: =('P&L'!B9+'P&L'!C9+'P&L'!D9)*Calculation!B4 -> 2601.2428 | C32: =('P&L'!E9+'P&L'!F9+'P&L'!G9)*Calculation!B4 -> 13024.113 | D32: =('P&L'!H9+'P&L'!I9+'P&L'!J9)*Calculation!B4 -> 15784.651 | E32: =('P&L'!K9+'P&L'!L9+'P&L'!M9)*Calculation!B4 -> 14716.374
A33: VAT to receive = VAT paid | B33: =(B13+B16+B17+B18+B19+B15)/Calculation!B2*Calculation!B4 -> 2454.943 | C33: =(C13+C16+C17+C18+C19+C15)/Calculation!B2*Calculation!B4 -> 9899.8504 | D33: =(D13+D16+D17+D18+D19+D15)/Calculation!B2*Calculation!B4 -> 11871.663 | E33: =(E13+E16+E17+E18+E19+E15)/Calculation!B2*Calculation!B4 -> 11108.608
A34: VAT to settle | B34: =B32-B33 -> 146.29983 | C34: =C32-C33 -> 3124.2628 | D34: =D32-D33 -> 3912.9878 | E34: =E32-E33 -> 3607.7658

Sheet Evaluation
A1: Evaluation
A3: Ratio's | B3: Begin | C3: End | D3: Norm | E3: Notes
A4: Solvability | B4: =Balances!E6/(Balances!E21+Balances!E14+Balances!E18) -> 0.53416728 | C4: =Balances!F33/(Balances!E46+Balances!E39+Balances!E45) -> 0.62215842 | D4: > 40% | E4: good solvability ratio due to high shareholders equity
A5: Current ratio | B5: =(Balances!B12+Balances!B13+Balances!B16)/Balances!E18 -> 18.220503 | C5: =(Balances!B37+Balances!B42)/Balances!E45 -> 19.095923 | D5: 1,5 - 4 | E5: high current ratio since we need a lot of initial investment to be able to export
A6: Quick ratio | B6: =B5 -> 18.220503 | C6: =C5 -> 19.095923 | D6: above 1 | E6: high liquidity because we have to pay lots of bills in the beginning
A7: Net working capital | B7: =(Balances!B12+Balances!B13+Balances!B16)-Balances!E18 -> 68572.041 | C7: =(Balances!B37+Balances!B42)-Balances!E45 -> 65285.854 | D7: above 0€ | E7: means the company has the financial resources to meet all of its short-term financial obligations
A8: Break Even Point Revenue PR Specialist | B8: ='Cost price or Hourly rate'!L61 -> 431.50697
A9: Break Even Point Revenue Photographer | B9: ='Cost price or Hourly rate'!L62 -> 354.38907
A10: Break Even Point Revenue Social Media Manager | B10: ='Cost price or Hourly rate'!L63 -> 696.57485
A11: ROE | B11: ='P&L'!B43/(Balances!E6+Balances!F33/2) -> 0.021025106 | D11: 0.08 | E11: there is a very small percentage of ROE since we make a minimal profit in the first year
A12: ACD | B12: ='inv+fin. budget'!V51/(Balances!E14+Balances!E18+Balances!E39+Balances!E45/2) -> 0.032269591 | D12: 0.06 | E12: if lower than 6% its good

Sheet Calculation
A1: Calculations
A2: VAT incl high | B2: 1.21
A3: VAT incl low | B3: 1.06
A4: VAT high | B4: 0.21
A5: VAT low | B5: 0.06
A7: Vacation Pay | B7: 0.08
A8: Employers costs | B8: 0.16
A11: FTE Monthly | B11: 40
